<sdf version='1.7'>
  <world name='default'>
    <model name='aruco_marker'>
      <link name='link'>
        <inertial>
          <pose>0 0 0 0 -0 0</pose>
          <mass>0.001</mass>
          <inertia>
            <ixx>3.75e-06</ixx>
            <ixy>0</ixy>
            <ixz>0</ixz>
            <iyy>1.875e-06</iyy>
            <iyz>0</iyz>
            <izz>1.875e-06</izz>
          </inertia>
        </inertial>
        <visual name='front_visual'>
          <pose>5e-05 0 0 0 -0 0</pose>
          <geometry>
            <box>
              <size>0.0001 0.15 0.15</size>
            </box>
          </geometry>
          <material>
            <script>
              <uri>model://aruco_marker/materials/scripts</uri>
              <uri>model://aruco_marker/materials/textures</uri>
              <name>Marker</name>
            </script>
          </material>
        </visual>
        <visual name='rear_visual'>
          <pose>-5e-05 0 0 0 -0 0</pose>
          <geometry>
            <box>
              <size>0.0001 0.15 0.15</size>
            </box>
          </geometry>
        </visual>
        <collision name='collision'>
          <pose>0 0 0 0 -0 0</pose>
          <geometry>
            <box>
              <size>0.0001 0.15 0.15</size>
            </box>
          </geometry>
          <max_contacts>10</max_contacts>
          <surface>
            <contact>
              <ode/>
            </contact>
            <bounce/>
            <friction>
              <torsional>
                <ode/>
              </torsional>
              <ode/>
            </friction>
          </surface>
        </collision>
        <self_collide>0</self_collide>
        <enable_wind>0</enable_wind>
        <kinematic>0</kinematic>
      </link>
      <pose>0 0.6 0.5 3.14159 -1.57074 -1.57074</pose>
    </model>
    <model name='ground_plane'>
      <static>1</static>
      <link name='link'>
        <collision name='collision'>
          <geometry>
            <plane>
              <normal>0 0 1</normal>
              <size>100 100</size>
            </plane>
          </geometry>
          <surface>
            <contact>
              <collide_bitmask>65535</collide_bitmask>
              <ode/>
            </contact>
            <friction>
              <ode>
                <mu>100</mu>
                <mu2>50</mu2>
              </ode>
              <torsional>
                <ode/>
              </torsional>
            </friction>
            <bounce/>
          </surface>
          <max_contacts>10</max_contacts>
        </collision>
        <visual name='visual'>
          <cast_shadows>0</cast_shadows>
          <geometry>
            <plane>
              <normal>0 0 1</normal>
              <size>100 100</size>
            </plane>
          </geometry>
          <material>
            <script>
              <uri>file://media/materials/scripts/gazebo.material</uri>
              <name>Gazebo/Grey</name>
            </script>
          </material>
        </visual>
        <self_collide>0</self_collide>
        <enable_wind>0</enable_wind>
        <kinematic>0</kinematic>
      </link>
    </model>
    <light name='sun' type='directional'>
      <cast_shadows>1</cast_shadows>
      <pose>0 0 10 0 -0 0</pose>
      <diffuse>0.8 0.8 0.8 1</diffuse>
      <specular>0.2 0.2 0.2 1</specular>
      <attenuation>
        <range>1000</range>
        <constant>0.9</constant>
        <linear>0.01</linear>
        <quadratic>0.001</quadratic>
      </attenuation>
      <direction>-0.5 0.1 -0.9</direction>
      <spot>
        <inner_angle>0</inner_angle>
        <outer_angle>0</outer_angle>
        <falloff>0</falloff>
      </spot>
    </light>
    <physics type='ode'>
      <max_step_size>0.001</max_step_size>
      <real_time_factor>1</real_time_factor>
      <real_time_update_rate>1000</real_time_update_rate>
    </physics>
    <gravity>0 0 -9.81</gravity>
    <magnetic_field>6e-06 2.3e-05 -4.2e-05</magnetic_field>
    <atmosphere type='adiabatic'/>
    <scene>
      <ambient>0.4 0.4 0.4 1</ambient>
      <background>0.7 0.7 0.7 1</background>
      <shadows>1</shadows>
    </scene>
    <audio>
      <device>default</device>
    </audio>
    <wind/>
    <spherical_coordinates>
      <surface_model>EARTH_WGS84</surface_model>
      <latitude_deg>0</latitude_deg>
      <longitude_deg>0</longitude_deg>
      <elevation>0</elevation>
      <heading_deg>0</heading_deg>
    </spherical_coordinates>
    <model name='table_top'>
      <pose>0 0 0.45 0 -0 0</pose>
      <static>1</static>
      <link name='link'>
        <collision name='collision'>
          <geometry>
            <cylinder>
              <radius>0.750001</radius>
              <length>0.1</length>
            </cylinder>
          </geometry>
          <max_contacts>10</max_contacts>
          <surface>
            <contact>
              <ode/>
            </contact>
            <bounce/>
            <friction>
              <torsional>
                <ode/>
              </torsional>
              <ode/>
            </friction>
          </surface>
        </collision>
        <visual name='visual'>
          <geometry>
            <cylinder>
              <radius>0.750001</radius>
              <length>0.1</length>
            </cylinder>
          </geometry>
          <material>
            <script>
              <name>Gazebo/Green</name>
              <uri>file://media/materials/scripts/gazebo.material</uri>
            </script>
          </material>
        </visual>
        <self_collide>0</self_collide>
        <enable_wind>0</enable_wind>
        <kinematic>0</kinematic>
        <inertial>
          <pose>0 0 0 0 -0 0</pose>
          <inertia>
            <ixx>1</ixx>
            <ixy>0</ixy>
            <ixz>0</ixz>
            <iyy>1</iyy>
            <iyz>0</iyz>
            <izz>1</izz>
          </inertia>
          <mass>1</mass>
        </inertial>
      </link>
    </model>
    <model name='box1'>
      <pose>0.4 0.5 0.55 0 -0 0</pose>
      <static>1</static>
      <link name='link'>
        <collision name='collision'>
          <geometry>
            <box>
              <size>0.1 0.1 0.1</size>
            </box>
          </geometry>
          <max_contacts>10</max_contacts>
          <surface>
            <contact>
              <ode/>
            </contact>
            <bounce/>
            <friction>
              <torsional>
                <ode/>
              </torsional>
              <ode/>
            </friction>
          </surface>
        </collision>
        <visual name='visual'>
          <geometry>
            <box>
              <size>0.1 0.1 0.1</size>
            </box>
          </geometry>
          <material>
            <script>
              <name>Gazebo/Red</name>
              <uri>file://media/materials/scripts/gazebo.material</uri>
            </script>
          </material>
        </visual>
        <self_collide>0</self_collide>
        <enable_wind>0</enable_wind>
        <kinematic>0</kinematic>
        <inertial>
          <pose>0 0 0 0 -0 0</pose>
          <inertia>
            <ixx>1</ixx>
            <ixy>0</ixy>
            <ixz>0</ixz>
            <iyy>1</iyy>
            <iyz>0</iyz>
            <izz>1</izz>
          </inertia>
          <mass>1</mass>
        </inertial>
      </link>
    </model>
    <model name='box2'>
      <pose>-0.4 0.3 0.6 0 -0 0</pose>
      <static>1</static>
      <link name='link'>
        <collision name='collision'>
          <geometry>
            <cylinder>
              <radius>0.05</radius>
              <length>0.2</length>
            </cylinder>
          </geometry>
          <max_contacts>10</max_contacts>
          <surface>
            <contact>
              <ode/>
            </contact>
            <bounce/>
            <friction>
              <torsional>
                <ode/>
              </torsional>
              <ode/>
            </friction>
          </surface>
        </collision>
        <visual name='visual'>
          <geometry>
            <cylinder>
              <radius>0.05</radius>
              <length>0.2</length>
            </cylinder>
          </geometry>
          <material>
            <script>
              <name>Gazebo/DarkGrey</name>
              <uri>file://media/materials/scripts/gazebo.material</uri>
            </script>
          </material>
        </visual>
        <self_collide>0</self_collide>
        <enable_wind>0</enable_wind>
        <kinematic>0</kinematic>
        <inertial>
          <pose>0 0 0 0 -0 0</pose>
          <inertia>
            <ixx>1</ixx>
            <ixy>0</ixy>
            <ixz>0</ixz>
            <iyy>1</iyy>
            <iyz>0</iyz>
            <izz>1</izz>
          </inertia>
          <mass>1</mass>
        </inertial>
      </link>
    </model>
    <state world_name='default'>
      <sim_time>278 564000000</sim_time>
      <real_time>184 804602845</real_time>
      <wall_time>1689757878 720547880</wall_time>
      <iterations>168248</iterations>
      <model name='aruco_marker'>
        <pose>0 0.6 0.500048 -1.5708 -1.57076 -3.14153</pose>
        <scale>1 1 1</scale>
        <link name='link'>
          <pose>0 0.6 0.500048 -1.5708 -1.57076 -3.14153</pose>
          <velocity>0 0 0 0 -0 0</velocity>
          <acceleration>0 0 -9.81 0 -0 0</acceleration>
          <wrench>0 0 -0.00981 0 -0 0</wrench>
        </link>
      </model>
      <model name='box1'>
        <pose>0.4 0.5 0.55 0 -0 0</pose>
        <scale>1 1 1</scale>
        <link name='link'>
          <pose>0.4 0.5 0.55 0 -0 0</pose>
          <velocity>0 0 0 0 -0 0</velocity>
          <acceleration>0 0 0 0 -0 0</acceleration>
          <wrench>0 0 0 0 -0 0</wrench>
        </link>
      </model>
      <model name='box2'>
        <pose>-0.4 0.3 0.6 0 -0 0</pose>
        <scale>1 1 1</scale>
        <link name='link'>
          <pose>-0.4 0.3 0.6 0 -0 0</pose>
          <velocity>0 0 0 0 -0 0</velocity>
          <acceleration>0 0 0 0 -0 0</acceleration>
          <wrench>0 0 0 0 -0 0</wrench>
        </link>
      </model>
      <model name='ground_plane'>
        <pose>0 0 0 0 -0 0</pose>
        <scale>1 1 1</scale>
        <link name='link'>
          <pose>0 0 0 0 -0 0</pose>
          <velocity>0 0 0 0 -0 0</velocity>
          <acceleration>0 0 0 0 -0 0</acceleration>
          <wrench>0 0 0 0 -0 0</wrench>
        </link>
      </model>
      <model name='table_leg'>
        <pose>0 0 0 0 -0 0</pose>
        <scale>1 1 1</scale>
        <link name='link'>
          <pose>0 0 0 0 -0 0</pose>
          <velocity>0 0 0 0 -0 0</velocity>
          <acceleration>0 0 0 0 -0 0</acceleration>
          <wrench>0 0 0 0 -0 0</wrench>
        </link>
      </model>
      <model name='table_top'>
        <pose>0 0 0.45 0 -0 0</pose>
        <scale>1 1 1</scale>
        <link name='link'>
          <pose>0 0 0.45 0 -0 0</pose>
          <velocity>0 0 0 0 -0 0</velocity>
          <acceleration>0 0 0 0 -0 0</acceleration>
          <wrench>0 0 0 0 -0 0</wrench>
        </link>
      </model>
      <model name='xarm6'>
        <pose>-1.5e-05 -9e-06 0.500005 0.000116 6.1e-05 1.57109</pose>
        <scale>1 1 1</scale>
        <link name='link1'>
          <pose>5e-06 -4e-06 0.767004 3.4e-05 -1.1e-05 1.57114</pose>
          <velocity>0 -0 -0 0 -0 -0.003209</velocity>
          <acceleration>-0.006439 0.086384 -3e-06 -0.544048 -0.47204 2.93587</acceleration>
          <wrench>-0.013908 0.186589 -6e-06 0 -0 0</wrench>
        </link>
        <link name='link2'>
          <pose>4e-06 -4e-06 0.767004 -1.57077 6e-06 1.57115</pose>
          <velocity>-0 -0 0 -0.01845 -7e-06 -0.003209</velocity>
          <acceleration>0.111855 4.05664 -0.651468 2.19982 0.536934 -0.032578</acceleration>
          <wrench>0.191272 6.93686 -1.11401 0 -0 0</wrench>
        </link>
        <link name='link3'>
          <pose>-8e-06 0.053498 1.0515 -1.57078 6e-06 1.57115</pose>
          <velocity>0.00017 0.005249 -0.000987 -0.01907 -7e-06 -0.003209</velocity>
          <acceleration>0.388113 3.24615 -2.2802 -1.72308 0.378911 2.25173</acceleration>
          <wrench>0.537149 4.49267 -3.15579 0 -0 0</wrench>
        </link>
        <link name='link4'>
          <pose>-4.3e-05 0.130996 0.709003 3.14158 -5e-06 -1.57035</pose>
          <velocity>0.000421 -0.001282 -0.002465 -0.01907 -7e-06 -0.003242</velocity>
          <acceleration>0.421305 -0.714566 -2.46896 -2.66552 -0.330741 -0.920557</acceleration>
          <wrench>0.469755 -0.796742 -2.75289 0 -0 0</wrench>
        </link>
        <link name='link5'>
          <pose>-4.3e-05 0.130996 0.709003 -3.01126 1.57078 -3.01082</pose>
          <velocity>0.000421 -0.001282 -0.002465 -0.019041 -7e-06 -0.003242</velocity>
          <acceleration>0.478965 -2.33328 -2.80414 1.19387 1.26928 2.97297</acceleration>
          <wrench>0.610681 -2.97493 -3.57528 0 -0 0</wrench>
        </link>
        <link name='link6'>
          <pose>-8.7e-05 0.227996 0.633003 1.69862 1.57078 -3.01332</pose>
          <velocity>0.000736 -0.002729 -0.004312 -0.019041 -6.7e-05 -0.003242</velocity>
          <acceleration>0.704988 -2.72706 -4.13077 0.923664 -0.043476 0.57703</acceleration>
          <wrench>0.077267 -0.298886 -0.452733 0 -0 0</wrench>
        </link>
        <link name='link_base'>
          <pose>-1.5e-05 -9e-06 0.500005 0.000116 6.1e-05 1.57109</pose>
          <velocity>0 0 -0 0 -0 0</velocity>
          <acceleration>-0 1e-06 2e-06 -2e-05 -1.5e-05 2e-05</acceleration>
          <wrench>-1e-06 4e-06 4e-06 0 -0 0</wrench>
        </link>
      </model>
      <light name='sun'>
        <pose>0 0 10 0 -0 0</pose>
      </light>
    </state>
    <gui fullscreen='0'>
      <camera name='user_camera'>
        <pose>2.02449 1.99172 1.84114 0 0.420995 -2.42</pose>
        <view_controller>orbit</view_controller>
        <projection_type>perspective</projection_type>
      </camera>
    </gui>
    <model name='table_leg'>
      <pose>0 0 0.215 0 -0 0</pose>
      <static>1</static>
      <link name='link'>
        <collision name='collision'>
          <geometry>
            <cylinder>
              <radius>0.1</radius>
              <length>0.43</length>
            </cylinder>
          </geometry>
          <max_contacts>10</max_contacts>
          <surface>
            <contact>
              <ode/>
            </contact>
            <bounce/>
            <friction>
              <torsional>
                <ode/>
              </torsional>
              <ode/>
            </friction>
          </surface>
        </collision>
        <visual name='visual'>
          <geometry>
            <cylinder>
              <radius>0.1</radius>
              <length>0.43</length>
            </cylinder>
          </geometry>
          <material>
            <script>
              <name>Gazebo/Black</name>
              <uri>file://media/materials/scripts/gazebo.material</uri>
            </script>
          </material>
        </visual>
        <self_collide>0</self_collide>
        <enable_wind>0</enable_wind>
        <kinematic>0</kinematic>
      </link>
    </model>
    <model name='xarm6'>
      <joint name='world_joint' type='fixed'>
        <pose relative_to='__model__'>0 0 0 0 -0 0</pose>
        <parent>world</parent>
        <child>link_base</child>
      </joint>
      <link name='link_base'>
        <pose relative_to='world_joint'>0 0 0 0 -0 0</pose>
        <inertial>
          <pose>0 0 0.09103 0 -0 0</pose>
          <mass>2.7</mass>
          <inertia>
            <ixx>0.00494875</ixx>
            <ixy>-3.5e-06</ixy>
            <ixz>1.25e-05</ixz>
            <iyy>0.00494174</iyy>
            <iyz>1.67e-06</iyz>
            <izz>0.002219</izz>
          </inertia>
        </inertial>
        <collision name='link_base_collision'>
          <pose>0 0 0 0 -0 0</pose>
          <geometry>
            <mesh>
              <scale>1 1 1</scale>
              <uri>file:////home/spear/xarm6-etf-lab/install/xarm_description/share/xarm_description/meshes/xarm6/visual/base.stl</uri>
            </mesh>
          </geometry>
          <surface>
            <contact>
              <ode/>
            </contact>
            <friction>
              <ode/>
              <torsional>
                <ode/>
              </torsional>
            </friction>
            <bounce/>
          </surface>
          <max_contacts>10</max_contacts>
        </collision>
        <visual name='link_base_visual'>
          <pose>0 0 0 0 -0 0</pose>
          <geometry>
            <mesh>
              <scale>1 1 1</scale>
              <uri>file:////home/spear/xarm6-etf-lab/install/xarm_description/share/xarm_description/meshes/xarm6/visual/base.stl</uri>
            </mesh>
          </geometry>
        </visual>
        <visual name='link_base_fixed_joint_lump__camera_link_left_visual_1'>
          <pose>1.5 -0.8 0.6 -0 0.3 2.8</pose>
          <geometry>
            <box>
              <size>0.04 0.1 0.04</size>
            </box>
          </geometry>
          <material>
            <script>
              <name>Gazebo/Grey</name>
              <uri>file://media/materials/scripts/gazebo.material</uri>
            </script>
          </material>
        </visual>
        <visual name='link_base_fixed_joint_lump__camera_link_right_visual_2'>
          <pose>1.5 0.8 0.6 -0 0.3 -2.78319</pose>
          <geometry>
            <box>
              <size>0.04 0.1 0.04</size>
            </box>
          </geometry>
          <material>
            <script>
              <name>Gazebo/Grey</name>
              <uri>file://media/materials/scripts/gazebo.material</uri>
            </script>
          </material>
        </visual>
        <self_collide>1</self_collide>
        <sensor name='camera_left' type='depth'>
          <visualize>1</visualize>
          <update_rate>10</update_rate>
          <camera>
            <horizontal_fov>1.089</horizontal_fov>
            <image>
              <format>R8G8B8</format>
              <width>640</width>
              <height>480</height>
            </image>
            <clip>
              <near>0.05</near>
              <far>8</far>
            </clip>
          </camera>
          <plugin name='camera_controller_left' filename='libgazebo_ros_camera.so'>
            <frame_name>camera_link_optical_left</frame_name>
            <min_depth>0.1</min_depth>
            <max_depth>8.0</max_depth>
          </plugin>
          <pose>1.5 -0.8 0.6 -0 0.3 2.8</pose>
        </sensor>
        <sensor name='camera_right' type='depth'>
          <visualize>1</visualize>
          <update_rate>10</update_rate>
          <camera>
            <horizontal_fov>1.089</horizontal_fov>
            <image>
              <format>R8G8B8</format>
              <width>640</width>
              <height>480</height>
            </image>
            <clip>
              <near>0.05</near>
              <far>8</far>
            </clip>
          </camera>
          <plugin name='camera_controller_right' filename='libgazebo_ros_camera.so'>
            <frame_name>camera_link_optical_right</frame_name>
            <min_depth>0.1</min_depth>
            <max_depth>8.0</max_depth>
          </plugin>
          <pose>1.5 0.8 0.6 -0 0.3 -2.78319</pose>
        </sensor>
        <enable_wind>0</enable_wind>
        <kinematic>0</kinematic>
      </link>
      <joint name='joint1' type='revolute'>
        <pose relative_to='link_base'>0 0 0.267 0 -0 0</pose>
        <parent>link_base</parent>
        <child>link1</child>
        <axis>
          <xyz>0 0 1</xyz>
          <limit>
            <lower>-6.28319</lower>
            <upper>6.28319</upper>
            <effort>50</effort>
            <velocity>3.14</velocity>
          </limit>
          <dynamics>
            <damping>1</damping>
            <friction>1</friction>
            <spring_reference>0</spring_reference>
            <spring_stiffness>0</spring_stiffness>
          </dynamics>
        </axis>
      </joint>
      <link name='link1'>
        <pose relative_to='joint1'>0 0 0 0 -0 0</pose>
        <inertial>
          <pose>-0.002 0.02692 -0.01332 0 -0 0</pose>
          <mass>2.16</mass>
          <inertia>
            <ixx>0.00539427</ixx>
            <ixy>1.095e-05</ixy>
            <ixz>1.635e-06</ixz>
            <iyy>0.0048979</iyy>
            <iyz>0.000793</iyz>
            <izz>0.00311573</izz>
          </inertia>
        </inertial>
        <collision name='link1_collision'>
          <pose>0 0 0 0 -0 0</pose>
          <geometry>
            <mesh>
              <scale>1 1 1</scale>
              <uri>file:////home/spear/xarm6-etf-lab/install/xarm_description/share/xarm_description/meshes/xarm6/visual/link1.stl</uri>
            </mesh>
          </geometry>
          <surface>
            <contact>
              <ode/>
            </contact>
            <friction>
              <ode/>
              <torsional>
                <ode/>
              </torsional>
            </friction>
            <bounce/>
          </surface>
          <max_contacts>10</max_contacts>
        </collision>
        <visual name='link1_visual'>
          <pose>0 0 0 0 -0 0</pose>
          <geometry>
            <mesh>
              <scale>1 1 1</scale>
              <uri>file:////home/spear/xarm6-etf-lab/install/xarm_description/share/xarm_description/meshes/xarm6/visual/link1.stl</uri>
            </mesh>
          </geometry>
        </visual>
        <self_collide>1</self_collide>
        <enable_wind>0</enable_wind>
        <kinematic>0</kinematic>
      </link>
      <joint name='joint2' type='revolute'>
        <pose relative_to='link1'>0 0 0 -1.5708 0 0</pose>
        <parent>link1</parent>
        <child>link2</child>
        <axis>
          <xyz>0 0 1</xyz>
          <limit>
            <lower>-2.059</lower>
            <upper>2.0944</upper>
            <effort>50</effort>
            <velocity>3.14</velocity>
          </limit>
          <dynamics>
            <damping>1</damping>
            <friction>1</friction>
            <spring_reference>0</spring_reference>
            <spring_stiffness>0</spring_stiffness>
          </dynamics>
        </axis>
      </joint>
      <link name='link2'>
        <pose relative_to='joint2'>0 0 0 0 -0 0</pose>
        <inertial>
          <pose>0.03531 -0.21398 0.03386 0 -0 0</pose>
          <mass>1.71</mass>
          <inertia>
            <ixx>0.0248674</ixx>
            <ixy>-0.00430651</ixy>
            <ixz>-0.00067797</ixz>
            <iyy>0.00485548</iyy>
            <iyz>0.00457245</iyz>
            <izz>0.0238783</izz>
          </inertia>
        </inertial>
        <collision name='link2_collision'>
          <pose>0 0 0 0 -0 0</pose>
          <geometry>
            <mesh>
              <scale>1 1 1</scale>
              <uri>file:////home/spear/xarm6-etf-lab/install/xarm_description/share/xarm_description/meshes/xarm6/visual/link2.stl</uri>
            </mesh>
          </geometry>
          <surface>
            <contact>
              <ode/>
            </contact>
            <friction>
              <ode/>
              <torsional>
                <ode/>
              </torsional>
            </friction>
            <bounce/>
          </surface>
          <max_contacts>10</max_contacts>
        </collision>
        <visual name='link2_visual'>
          <pose>0 0 0 0 -0 0</pose>
          <geometry>
            <mesh>
              <scale>1 1 1</scale>
              <uri>file:////home/spear/xarm6-etf-lab/install/xarm_description/share/xarm_description/meshes/xarm6/visual/link2.stl</uri>
            </mesh>
          </geometry>
        </visual>
        <self_collide>1</self_collide>
        <enable_wind>0</enable_wind>
        <kinematic>0</kinematic>
      </link>
      <joint name='joint3' type='revolute'>
        <pose relative_to='link2'>0.0535 -0.2845 0 0 -0 0</pose>
        <parent>link2</parent>
        <child>link3</child>
        <axis>
          <xyz>0 0 1</xyz>
          <limit>
            <lower>-3.927</lower>
            <upper>0.19198</upper>
            <effort>32</effort>
            <velocity>3.14</velocity>
          </limit>
          <dynamics>
            <damping>1</damping>
            <friction>1</friction>
            <spring_reference>0</spring_reference>
            <spring_stiffness>0</spring_stiffness>
          </dynamics>
        </axis>
      </joint>
      <link name='link3'>
        <pose relative_to='joint3'>0 0 0 0 -0 0</pose>
        <inertial>
          <pose>0.06781 0.10749 0.01457 0 -0 0</pose>
          <mass>1.384</mass>
          <inertia>
            <ixx>0.0053694</ixx>
            <ixy>0.0014185</ixy>
            <ixz>-0.00092094</ixz>
            <iyy>0.0032423</iyy>
            <iyz>-0.00169178</iyz>
            <izz>0.00501731</izz>
          </inertia>
        </inertial>
        <collision name='link3_collision'>
          <pose>0 0 0 0 -0 0</pose>
          <geometry>
            <mesh>
              <scale>1 1 1</scale>
              <uri>file:////home/spear/xarm6-etf-lab/install/xarm_description/share/xarm_description/meshes/xarm6/visual/link3.stl</uri>
            </mesh>
          </geometry>
          <surface>
            <contact>
              <ode/>
            </contact>
            <friction>
              <ode/>
              <torsional>
                <ode/>
              </torsional>
            </friction>
            <bounce/>
          </surface>
          <max_contacts>10</max_contacts>
        </collision>
        <visual name='link3_visual'>
          <pose>0 0 0 0 -0 0</pose>
          <geometry>
            <mesh>
              <scale>1 1 1</scale>
              <uri>file:////home/spear/xarm6-etf-lab/install/xarm_description/share/xarm_description/meshes/xarm6/visual/link3.stl</uri>
            </mesh>
          </geometry>
        </visual>
        <self_collide>1</self_collide>
        <enable_wind>0</enable_wind>
        <kinematic>0</kinematic>
      </link>
      <joint name='joint4' type='revolute'>
        <pose relative_to='link3'>0.0775 0.3425 0 -1.5708 0 0</pose>
        <parent>link3</parent>
        <child>link4</child>
        <axis>
          <xyz>0 0 1</xyz>
          <limit>
            <lower>-6.28319</lower>
            <upper>6.28319</upper>
            <effort>32</effort>
            <velocity>3.14</velocity>
          </limit>
          <dynamics>
            <damping>1</damping>
            <friction>1</friction>
            <spring_reference>0</spring_reference>
            <spring_stiffness>0</spring_stiffness>
          </dynamics>
        </axis>
      </joint>
      <link name='link4'>
        <pose relative_to='joint4'>0 0 0 0 -0 0</pose>
        <inertial>
          <pose>-0.00021 0.02578 -0.02538 0 -0 0</pose>
          <mass>1.115</mass>
          <inertia>
            <ixx>0.00439263</ixx>
            <ixy>5.028e-05</ixy>
            <ixz>1.374e-05</ixz>
            <iyy>0.0040077</iyy>
            <iyz>0.00045338</iyz>
            <izz>0.00110321</izz>
          </inertia>
        </inertial>
        <collision name='link4_collision'>
          <pose>0 0 0 0 -0 0</pose>
          <geometry>
            <mesh>
              <scale>1 1 1</scale>
              <uri>file:////home/spear/xarm6-etf-lab/install/xarm_description/share/xarm_description/meshes/xarm6/visual/link4.stl</uri>
            </mesh>
          </geometry>
          <surface>
            <contact>
              <ode/>
            </contact>
            <friction>
              <ode/>
              <torsional>
                <ode/>
              </torsional>
            </friction>
            <bounce/>
          </surface>
          <max_contacts>10</max_contacts>
        </collision>
        <visual name='link4_visual'>
          <pose>0 0 0 0 -0 0</pose>
          <geometry>
            <mesh>
              <scale>1 1 1</scale>
              <uri>file:////home/spear/xarm6-etf-lab/install/xarm_description/share/xarm_description/meshes/xarm6/visual/link4.stl</uri>
            </mesh>
          </geometry>
        </visual>
        <self_collide>1</self_collide>
        <enable_wind>0</enable_wind>
        <kinematic>0</kinematic>
      </link>
      <joint name='joint5' type='revolute'>
        <pose relative_to='link4'>0 0 0 1.5708 -0 0</pose>
        <parent>link4</parent>
        <child>link5</child>
        <axis>
          <xyz>0 0 1</xyz>
          <limit>
            <lower>-1.69297</lower>
            <upper>3.14159</upper>
            <effort>32</effort>
            <velocity>3.14</velocity>
          </limit>
          <dynamics>
            <damping>1</damping>
            <friction>1</friction>
            <spring_reference>0</spring_reference>
            <spring_stiffness>0</spring_stiffness>
          </dynamics>
        </axis>
      </joint>
      <link name='link5'>
        <pose relative_to='joint5'>0 0 0 0 -0 0</pose>
        <inertial>
          <pose>0.05428 0.01781 0.00543 0 -0 0</pose>
          <mass>1.275</mass>
          <inertia>
            <ixx>0.00120276</ixx>
            <ixy>0.000492428</ixy>
            <ixz>-0.00039147</ixz>
            <iyy>0.0022876</iyy>
            <iyz>-0.0001235</iyz>
            <izz>0.0026866</izz>
          </inertia>
        </inertial>
        <collision name='link5_collision'>
          <pose>0 0 0 0 -0 0</pose>
          <geometry>
            <mesh>
              <scale>1 1 1</scale>
              <uri>file:////home/spear/xarm6-etf-lab/install/xarm_description/share/xarm_description/meshes/xarm6/visual/link5.stl</uri>
            </mesh>
          </geometry>
          <surface>
            <contact>
              <ode/>
            </contact>
            <friction>
              <ode/>
              <torsional>
                <ode/>
              </torsional>
            </friction>
            <bounce/>
          </surface>
          <max_contacts>10</max_contacts>
        </collision>
        <visual name='link5_visual'>
          <pose>0 0 0 0 -0 0</pose>
          <geometry>
            <mesh>
              <scale>1 1 1</scale>
              <uri>file:////home/spear/xarm6-etf-lab/install/xarm_description/share/xarm_description/meshes/xarm6/visual/link5.stl</uri>
            </mesh>
          </geometry>
        </visual>
        <self_collide>1</self_collide>
        <enable_wind>0</enable_wind>
        <kinematic>0</kinematic>
      </link>
      <joint name='joint6' type='revolute'>
        <pose relative_to='link5'>0.076 0.097 0 -1.5708 0 0</pose>
        <parent>link5</parent>
        <child>link6</child>
        <axis>
          <xyz>0 0 1</xyz>
          <limit>
            <lower>-6.28319</lower>
            <upper>6.28319</upper>
            <effort>20</effort>
            <velocity>3.14</velocity>
          </limit>
          <dynamics>
            <damping>1</damping>
            <friction>1</friction>
            <spring_reference>0</spring_reference>
            <spring_stiffness>0</spring_stiffness>
          </dynamics>
        </axis>
      </joint>
      <link name='link6'>
        <pose relative_to='joint6'>0 0 0 0 -0 0</pose>
        <inertial>
          <pose>0 0.00064 -0.00952 0 -0 0</pose>
          <mass>0.1096</mass>
          <inertia>
            <ixx>4.5293e-05</ixx>
            <ixy>0</ixy>
            <ixz>0</ixz>
            <iyy>4.8111e-05</iyy>
            <iyz>0</iyz>
            <izz>7.9715e-05</izz>
          </inertia>
        </inertial>
        <collision name='link6_collision'>
          <pose>0 0 0 0 -0 0</pose>
          <geometry>
            <mesh>
              <scale>1 1 1</scale>
              <uri>file:////home/spear/xarm6-etf-lab/install/xarm_description/share/xarm_description/meshes/xarm6/visual/link6.stl</uri>
            </mesh>
          </geometry>
          <surface>
            <contact>
              <ode/>
            </contact>
            <friction>
              <ode/>
              <torsional>
                <ode/>
              </torsional>
            </friction>
            <bounce/>
          </surface>
          <max_contacts>10</max_contacts>
        </collision>
        <visual name='link6_visual'>
          <pose>0 0 0 0 -0 0</pose>
          <geometry>
            <mesh>
              <scale>1 1 1</scale>
              <uri>file:////home/spear/xarm6-etf-lab/install/xarm_description/share/xarm_description/meshes/xarm6/visual/link6.stl</uri>
            </mesh>
          </geometry>
        </visual>
        <self_collide>1</self_collide>
        <enable_wind>0</enable_wind>
        <kinematic>0</kinematic>
      </link>
      <static>0</static>
      <plugin name='gazebo_ros2_control' filename='libgazebo_ros2_control.so'>
        <robot_sim_type>gazebo_ros2_control/GazeboSystem</robot_sim_type>
        <parameters>/tmp/launch_params_sbdgiu6p</parameters>
      </plugin>
      <pose>0 0 0.5 0 -0 1.571</pose>
    </model>
  </world>
</sdf>
